// throw文
try {
    console.log('通常処理');
    // ここでエラー発生
    
    
    console.log('その後の処理');
} catch(error) {
    
} finally {
    console.log('最終処理');
}
